<?xml version="1.0"?>

<robot xmlns:xacro="http://www.ros.org/wiki/xacro">
    <xacro:include filename="material.xacro"/>
    
    
<!-- base link -->

    <link name="base_link"/>

<!-- chassis link -->

    <link name="chassis">
        <inertial>
            <origin xyz="0.35 0.0 0.0" rpy="0.0 0.0 0.0"/>
            <mass value="9.0"/>
            <inertia ixx="0.1" ixy="0.0" ixz="0.0" iyy="0.1" iyz="0.0" izz="0.1"/>
        </inertial>
        <visual name="">
            <origin xyz="0.25 0.0 0.1" rpy="0.0 0.0 0.0"/>
            <geometry>
                <box size="0.6 0.4 0.2"/>
            </geometry>
            <material name="blue"/>
        </visual>
        <collision>
            <origin xyz="0.25 0.0 0.1" rpy="0.0 0.0 0.0"/>
            <geometry>
                <box size="0.6 0.4 0.2"/>
            </geometry>
        </collision>
    </link>

    <joint name="base_link_to_chassis" type="fixed">
        <origin xyz="-0.1 0.0 0.05" rpy="0.0 0.0 0.0"/>
        <parent link="base_link"/>
        <child link="chassis"/>
        
    </joint>
<!-- shaft link -->

    <link name="shaft">
        <inertial>
            <origin xyz="-.01 0.0 0.0" rpy="0.0 0.0 0.0"/>
            <mass value="0.5"/>
            <inertia ixx="0.1" ixy="0.0" ixz="0.0" iyy="0.1" iyz="0.0" izz="0.1"/>
        </inertial>

        <visual name="">
            <origin xyz="-0.0 0.0 0.0" rpy="1.57 0.0 0.0"/>
            <geometry>
                <cylinder radius="0.03" length="0.5"/> 
            </geometry>
            <material name="orange"/>
        </visual>
        <collision>
            <origin xyz="-0.1 0.0 0.0" rpy="1.57 0.0 0.0"/>
            <geometry>
                <cylinder radius="0.03" length="0.5"/> 
            </geometry>
        </collision>
    </link>
<!-- joint chassis to shaft -->
    <joint name="base_link_to_shaft" type="fixed">
        <parent link="base_link"/>
        <child link="shaft"/>
        <origin xyz="0.0 0.0 0.05"/>
    </joint>
<!-- right wheel link -->
    <link name="right_wheel">

        <inertial>
            <origin xyz="0.0 0.0 0.0" rpy="0.0 0.0 0.0"/>
            <mass value="5"/>
            <inertia ixx="0.1" ixy="0.0" ixz="0.0" iyy="0.1" iyz="0.0" izz="0.1"/>
        </inertial>
        <visual name="">
            <geometry>
                <cylinder radius="0.1" length="0.04"/>
            </geometry>
            <material name="black"/>
        </visual>
        <collision>
            
            <geometry>
                <cylinder radius="0.1" length="0.04"/>
            </geometry>
        </collision>
    </link>

<!-- joint shaft with right wheel -->
    <joint name="base_link_to_right_wheel" type="continuous">
        <origin xyz="0.0 -0.25 0.05" rpy="1.57 0.0 0.0"/>
        <parent link="base_link"/>
        <child link="right_wheel"/>
        <axis xyz="0.0 0.0 -1"/>
        <limit effort="10000" velocity="1000"/>
        <joint_properties damping="1.0" friction="1.0"/>    </joint>
<!-- lift wheel -->
    <link name="left_wheel">

        <inertial>
            <origin xyz="0.0 0.0 0.0" rpy="0.0 0.0 0.0"/>
            <mass value="5"/>
            <inertia ixx="0.1" ixy="0.0" ixz="0.0" iyy="0.1" iyz="0.0" izz="0.1"/>
        </inertial>
        <visual name="">
            <!-- <origin xyz="0.0 0.25 0.0" rpy="-1.57 0.0 0.0"/> -->

            <geometry>
                <cylinder radius="0.1" length="0.04"/>
            </geometry>
            <material name="black"/>
        </visual>
        <collision>
            <!-- <origin xyz="0.0 0.25 0.0" rpy="-1.57 0.0 0.0"/> -->
            
            <geometry>
                <cylinder radius="0.1" length="0.04"/>
            </geometry>
        </collision>
    </link>
<!-- joint shaft with right wheel -->
    <joint name="base_link_to_left_wheel" type="continuous">
        <origin xyz="0.0 0.25 0.05" rpy="-1.57 0.0 0.0"/>
        <parent link="base_link"/>
        <child link="left_wheel"/>
        <axis xyz="0.0 0.0 1"/>
        <limit effort="10000" velocity="1000"/>
        <joint_properties damping="1.0" friction="1.0"/>
    </joint>

    <link name="caster_wheel">
        <inertial>
            <origin xyz="0.0 0.0 0.0" rpy="0.0 0.0 0.0"/>
            <mass value="0.0"/>
            <inertia ixx="0.0" ixy="0.0" ixz="0.0" iyy="0.0" iyz="0.0" izz="0.0"/>
        </inertial>
        <visual >
            <origin xyz="0.0 0.0 0.0" rpy="0.0 0.0 0.0"/>
            <geometry>
                <sphere radius="0.1"/>
            </geometry>
            <surface>
                <friction>
                    <ode>
                        <mu>0.0</mu>
                        <mu2>0.0</mu2>
                        <fdir1>0.0 0.0 0.0</fdir1>
                        <slip1>1.0</slip1>
                        <slip2>1.0</slip2>
                    </ode>
                </friction>
            </surface>
            <material name = "white_lin">
                <color rgba="1.0 1.0 1.0 1.0"/>
            </material>
                
        </visual>
        <collision>
            <origin xyz="0.0 0.0 0.0" rpy="0.0 0.0 0.0"/>
            <geometry>
                <sphere radius="0.1"/>
            </geometry>
            
        </collision>
    </link>
<!-- joint caster wheel with base linkk -->
    <joint name="base_link_to_custer_wheel" type= "fixed">
        <origin xyz="0.3 0.0 0.05" rpy="0.0 0.0 0.0"/>
        <parent link="base_link"/>
        <child link="caster_wheel"/>
        <axis xyz="0.0 0.0 0.0"/>
        <limit lower="0.0" upper="0.0" effort="0.0" velocity="0.0"/>
    </joint>

    
</robot>